<?xml version="1.0"?>

<robot name="kuka_model" xmlns:xacro="http://wiki.ros.org/xacro">
	<xacro:include filename="$(find kuka_model)/urdf/kuka_model_def_macro.xacro" />

		<link name="slide">
			<visual>
				<geometry>
					<box size="5 0.2 0.1"/>
				</geometry>
				<origin rpy="0 0 0" xyz="0 0 0.05"/>
				<material name="Cyan">
					<color rgba="0 1.0 1.0 1.0"/>
				</material>
			</visual>
			<collision>
				<geometry>
					<box size="5 0.2 0.1"/>
				</geometry>
				<origin rpy="0 0 0" xyz="0 0 0.05"/>
			</collision>
			<inertial>
				<mass value="1"/>
				<inertia ixx="1.0" ixy="0.0" ixz="0.0" iyy="1.0" iyz="0.0" izz="1.0"/>
			</inertial>
		</link>

		<joint name="prism_slide" type="prismatic">
			<parent link="slide"/>
			<child link="box_slide"/>
	            <limit effort="10" velocity="1" lower="-2.3" upper="2.3"/>
	            <origin xyz="0 0 0.1" />
			<axis xyz="1 0 0"/>
			<dynamics damping="50" friction="1"/>
		</joint>
	
		
		
		<link name="box_slide">
			<visual>
				<geometry>
					<box size="0.2 0.2 0.3"/>
				</geometry>
				<origin rpy="0 0 0" xyz="0 0 0.15"/>
				<material name="Cyan">
					<color rgba="0 1.0 1.0 1.0"/>
				</material>
			</visual>
			<collision>
				<geometry>
					<box size="0.2 0.2 0.3"/>
				</geometry>
				<origin rpy="0 0 0" xyz="0 0 0.15"/>
			</collision>
			<inertial>
				<mass value="1"/>
				<inertia ixx="1.0" ixy="0.0" ixz="0.0" iyy="1.0" iyz="0.0" izz="1.0"/>
			</inertial>
		</link>

		<joint name="fixed_joint" type="fixed">
			<parent link="box_slide"/>
			<child link="base_link"/>
			<origin xyz="0 0 0.3"/>
		</joint>
	

	<xacro:include filename="$(find kuka_model)/urdf/kuka_model_def.xacro" />	
		
</robot>
