<?xml version="1.0" encoding="utf-8"?>
<!-- =================================================================================== -->
<!-- |    This document was autogenerated by xacro from kuka_slide.xacro               | -->
<!-- |    EDITING THIS FILE BY HAND IS NOT RECOMMENDED                                 | -->
<!-- =================================================================================== -->
<robot name="kuka_model">
  <link name="slide">
    <visual>
      <geometry>
        <box size="5 0.2 0.1"/>
      </geometry>
      <origin rpy="0 0 0" xyz="0 0 0.05"/>
      <material name="red">
        <color rgba="207 0 15 1"/>
      </material>
    </visual>
    <collision>
      <geometry>
        <box size="5 0.2 0.1"/>
      </geometry>
      <origin rpy="0 0 0" xyz="0 0 0.05"/>
    </collision>
    <inertial>
      <mass value="1"/>
      <inertia ixx="1.0" ixy="0.0" ixz="0.0" iyy="1.0" iyz="0.0" izz="1.0"/>
    </inertial>
  </link>
  <joint name="prism_slide" type="prismatic">
    <parent link="slide"/>
    <child link="box_slide"/>
    <limit effort="10" lower="-2.3" upper="2.3" velocity="1"/>
    <origin xyz="0 0 0"/>
    <axis xyz="1 0 0"/>
    <dynamics damping="50" friction="1"/>
  </joint>
  <link name="box_slide">
    <visual>
      <geometry>
        <box size="0.2 0.2 0.3"/>
      </geometry>
      <origin rpy="0 0 0" xyz="0 0 0.1"/>
      <material name="red">
        <color rgba="207 0 15 1"/>
      </material>
    </visual>
    <collision>
      <geometry>
        <box size="0.2 0.2 0.3"/>
      </geometry>
      <origin rpy="0 0 0" xyz="0 0 0.1"/>
    </collision>
    <inertial>
      <mass value="1"/>
      <inertia ixx="1.0" ixy="0.0" ixz="0.0" iyy="1.0" iyz="0.0" izz="1.0"/>
    </inertial>
  </link>
  <joint name="fixed_joint" type="fixed">
    <parent link="box_slide"/>
    <child link="base_link"/>
  </joint>
  <link name="base_link">
    <visual>
      <geometry>
        <cylinder length="0.2" radius="0.02"/>
      </geometry>
      <origin rpy="0 0 0" xyz="0 0 0.1"/>
      <material name="yellow">
        <color rgba="1 1 0 1"/>
      </material>
    </visual>
    <collision>
      <geometry>
        <cylinder length="0.21" radius="0.2"/>
      </geometry>
      <origin rpy="0 0 0" xyz="0 0 0.1"/>
    </collision>
    <inertial>
      <mass value="1"/>
      <inertia ixx="1.0" ixy="0.0" ixz="0.0" iyy="1.0" iyz="0.0" izz="1.0"/>
    </inertial>
  </link>
  <joint name="joint_1" type="revolute">
    <parent link="base_link"/>
    <child link="link_1"/>
    <limit effort="176" lower="-1.48277777778" upper="1.48277777778" velocity="98"/>
    <origin xyz="0 0 0.2"/>
    <axis xyz="0 0 1"/>
    <dynamics damping="50" friction="1"/>
  </joint>
  <link name="link_1">
    <visual>
      <geometry>
        <cylinder length="0.2" radius="0.02"/>
      </geometry>
      <origin rpy="0 0 0" xyz="0 0 0.1"/>
      <material name="red">
        <color rgba="0 0 1 1"/>
      </material>
    </visual>
    <collision>
      <geometry>
        <cylinder length="0.21" radius="0.03"/>
      </geometry>
      <origin rpy="0 0 0" xyz="0 0 0.1"/>
    </collision>
    <inertial>
      <mass value="1"/>
      <inertia ixx="1.0" ixy="0.0" ixz="0.0" iyy="1.0" iyz="0.0" izz="1.0"/>
    </inertial>
  </link>
  <joint name="joint_2" type="revolute">
    <parent link="link_1"/>
    <child link="link_2"/>
    <limit effort="100" lower="-1.04666666667" upper="1.04666666667" velocity="98"/>
    <origin xyz="0 0 0.2"/>
    <axis xyz="1 0 0"/>
    <dynamics damping="50" friction="1"/>
  </joint>
  <link name="link_2">
    <visual>
      <geometry>
        <cylinder length="0.2" radius="0.02"/>
      </geometry>
      <origin rpy="0 0 0" xyz="0 0 0.1"/>
      <material name="red">
        <color rgba="0 0 1 1"/>
      </material>
    </visual>
    <collision>
      <geometry>
        <cylinder length="0.21" radius="0.03"/>
      </geometry>
      <origin rpy="0 0 0" xyz="0 0 0.1"/>
    </collision>
    <inertial>
      <mass value="1"/>
      <inertia ixx="1.0" ixy="0.0" ixz="0.0" iyy="1.0" iyz="0.0" izz="1.0"/>
    </inertial>
  </link>
  <joint name="joint_3" type="revolute">
    <parent link="link_2"/>
    <child link="link_3"/>
    <limit effort="110" lower="-1.48277777778" upper="1.48277777778" velocity="100"/>
    <origin xyz="0 0 0.2"/>
    <axis xyz="0 0 1"/>
    <dynamics damping="50" friction="1"/>
  </joint>
  <link name="link_3">
    <visual>
      <geometry>
        <cylinder length="0.2" radius="0.02"/>
      </geometry>
      <origin rpy="0 0 0" xyz="0 0 0.1"/>
      <material name="red">
        <color rgba="0 0 1 1"/>
      </material>
    </visual>
    <collision>
      <geometry>
        <cylinder length="0.21" radius="0.03"/>
      </geometry>
      <origin rpy="0 0 0" xyz="0 0 0.1"/>
    </collision>
    <inertial>
      <mass value="1"/>
      <inertia ixx="1.0" ixy="0.0" ixz="0.0" iyy="1.0" iyz="0.0" izz="1.0"/>
    </inertial>
  </link>
  <joint name="joint_4" type="revolute">
    <parent link="link_3"/>
    <child link="link_4"/>
    <limit effort="110" lower="-1.04666666667" upper="1.04666666667" velocity="130.0"/>
    <origin xyz="0 0 0.2"/>
    <axis xyz="1 0 0"/>
    <dynamics damping="50" friction="1"/>
  </joint>
  <link name="link_4">
    <visual>
      <geometry>
        <cylinder length="0.2" radius="0.02"/>
      </geometry>
      <origin rpy="0 0 0" xyz="0 0 0.1"/>
      <material name="red">
        <color rgba="0 0 1 1"/>
      </material>
    </visual>
    <collision>
      <geometry>
        <cylinder length="0.21" radius="0.03"/>
      </geometry>
      <origin rpy="0 0 0" xyz="0 0 0.1"/>
    </collision>
    <inertial>
      <mass value="1"/>
      <inertia ixx="1.0" ixy="0.0" ixz="0.0" iyy="1.0" iyz="0.0" izz="1.0"/>
    </inertial>
  </link>
  <joint name="joint_5" type="revolute">
    <parent link="link_4"/>
    <child link="link_5"/>
    <limit effort="110" lower="-1.48277777778" upper="1.48277777778" velocity="140"/>
    <origin xyz="0 0 0.2"/>
    <axis xyz="0 0 1"/>
    <dynamics damping="50" friction="1"/>
  </joint>
  <link name="link_5">
    <visual>
      <geometry>
        <cylinder length="0.2" radius="0.02"/>
      </geometry>
      <origin rpy="0 0 0" xyz="0 0 0.1"/>
      <material name="red">
        <color rgba="0 0 1 1"/>
      </material>
    </visual>
    <collision>
      <geometry>
        <cylinder length="0.21" radius="0.03"/>
      </geometry>
      <origin rpy="0 0 0" xyz="0 0 0.1"/>
    </collision>
    <inertial>
      <mass value="1"/>
      <inertia ixx="1.0" ixy="0.0" ixz="0.0" iyy="1.0" iyz="0.0" izz="1.0"/>
    </inertial>
  </link>
  <joint name="joint_6" type="revolute">
    <parent link="link_5"/>
    <child link="link_6"/>
    <limit effort="40" lower="-1.04666666667" upper="1.04666666667" velocity="180"/>
    <origin xyz="0 0 0.2"/>
    <axis xyz="1 0 0"/>
    <dynamics damping="50" friction="1"/>
  </joint>
  <link name="link_6">
    <visual>
      <geometry>
        <cylinder length="0.2" radius="0.02"/>
      </geometry>
      <origin rpy="0 0 0" xyz="0 0 0.1"/>
      <material name="red">
        <color rgba="0 0 1 1"/>
      </material>
    </visual>
    <collision>
      <geometry>
        <cylinder length="0.21" radius="0.03"/>
      </geometry>
      <origin rpy="0 0 0" xyz="0 0 0.1"/>
    </collision>
    <inertial>
      <mass value="1"/>
      <inertia ixx="1.0" ixy="0.0" ixz="0.0" iyy="1.0" iyz="0.0" izz="1.0"/>
    </inertial>
  </link>
  <joint name="joint_7" type="revolute">
    <parent link="link_6"/>
    <child link="link_7"/>
    <limit effort="40" lower="-1.52638888889" upper="1.52638888889" velocity="180"/>
    <origin xyz="0 0 0.2"/>
    <axis xyz="0 0 1"/>
    <dynamics damping="50" friction="1"/>
  </joint>
  <link name="link_7">
    <visual>
      <geometry>
        <cylinder length="0.2" radius="0.02"/>
      </geometry>
      <origin rpy="0 0 0" xyz="0 0 0.1"/>
      <material name="red">
        <color rgba="0 0 1 1"/>
      </material>
    </visual>
    <collision>
      <geometry>
        <cylinder length="0.21" radius="0.03"/>
      </geometry>
      <origin rpy="0 0 0" xyz="0 0 0.1"/>
    </collision>
    <inertial>
      <mass value="1"/>
      <inertia ixx="1.0" ixy="0.0" ixz="0.0" iyy="1.0" iyz="0.0" izz="1.0"/>
    </inertial>
  </link>
</robot>

